Workbook

Sheet Organized Input Output
A1: RWH Input-Output Data | C1: RED IS INPUT ONLY, TYPE NEW VALUES INTO RED | P1: Variable Efficiency | Q1: ='Flow Rate'!$AE$31 -> 0.30149324
A2: Team J-9 | Z2: Dysinfection System Settings | AA2: UV System | AC2: Chemical System
AA3: System | AC3: Chlorine | AD3: n
B4: Input Data | F4: Cf_exp | G4: 13743 | H4: total maintenance days | I4: =Maintainance!M7+'Ozone-Energy'!Z5+ IF('Organized Input Output'!AA9> 0, 4, 0)+'Ozone-Energy'!U4 -> 18 | K4: Total Cost | L4: =Costs!B64 -> 54218.769 | M4: Overall Satifaction | N4: ='Stakeholder Satisfaction'!K15 -> 0.94014126 | P4: On-Demand Flow Rate | Q4: ='Flow Rate'!L31 -> 41.469023 | AA4: 36W | AB4: n
P5: Filter Settings | Q5: Filter size | R5: Present? | S5: Cf Pa/(m/s) | T5: Actual filter life (L) | U5: Filter Life Data (L) | X5: Filter location (B or A) | AA5: 40W | AB5: n | AC5: Ozone | AD5: y
A6: Parameters | B6: Gravity acceleration | C6: g | D6: 9.81 | E6: m/s^2 | G6: Catchment Settings | H6: Roof catchment area (m^2) - (50, 100) | I6: additional catchment area (m^2) | J6: Total catchment area (m^2) | K6: Catchment tank (L) - (400 or 1,500 or 2500 or 5,000 or 10,000) | L6: Catchment Tank initial Volume (L) | U6: No pre filter | V6: 5 um pre | W6: 200 um pre | AA6: 50W | AB6: y
B7: Pipe diameter | C7: D | D7: 0.02 | E7: m | H7: 100 | I7: 1000 | J7: =H7+I7 -> 1100 | K7: 2500 | L7: 0 | Q7: 1 um filter | R7: y | S7: =0.167*$G$4 -> 2295.081 | T7: =IF($R$8 = "y", $V$7, IF($R$9 = "y", $W$7, $U$7)) -> 20000 | U7: 5000 | V7: 20000 | W7: 15000 | Z7: Power System Settings | AA7: Solar Energy | AE7: Diesel
B8: Pipe area | C8: A | D8: =($D$7/2)^2*PI() -> 0.00031415927 | E8: m^2 | G8: Storag Tank Settings | H8: Storage Tank Volume (m3) | I8: storage tank location x (m) | J8: storage tank location y (m) | K8: Distance to storage tank (m) | L8: Storage tank height (m) | M8: Storage tank tower height (m) | N8: Storage tank total height (m) | Q8: 5 um filter | R8: y | S8: =IF( R8 = "y", 0.0833*$G$4, 0) -> 1144.7919 | T8: =IF($R$8 = "n", "", IF($R$9 = "y", $W$8, $U$8)) -> 20000 | U8: 10000 | W8: 20000 | AA8: Model (260, 80, 306) | AB8: Efficency | AC8: Quantities | AD8: Total Area(m^2) | AE8: Model | AF8: Present?
B9: Density of water | C9: ρ | D9: 1000 | E9: [kg/m3] | H9: 20 | I9: 40 | J9: -10 | K9: =SQRT(I9^2 +J9^2 +L9^2) -> 41.533119 | L9: 5 | M9: 21 | N9: =$L$9+$M$9 -> 26 | Q9: 200 um filter | R9: y | S9: =IF( R9= "y", 0.00417*$G$4, 0) -> 57.30831 | T9: =IF($R$9 = "n", "", $U$9) -> 20000 | U9: 20000 | AA9: 80 | AB9: =IF($AA$9=260,0.17,IF($AA$9=80,0.15,IF($AA$9=306,0.16,0))) -> 0.15 | AC9: 5 | AD9: =$AC$9*1.6 -> 8 | AE9: 4000W 2 cyl. | AF9: n
B10: Pipe friction factor | C10: f | D10: 0.05 | G10: Pump Settings | H10: Which pump? (A=1, B=2, C=3) | I10: a | J10: b | K10: c | L10: A | M10: B | N10: Q_Max | Q10: Total | S10: =SUM($S$7:$S$9) -> 3497.1812 | AA10: Inverter | AB10: =IF(AA9 > 0, "y", "n") -> y | AC10: =IF(AB10 = "y", 1, 0) -> 1
B11: Loss coefficient Catchment to Storage | C11: K | D11: 10 | H11: 3 | I11: =IF($H$11=1,-0.0172,IF($H$11=2,-0.0039,IF($H$11=3,-0.0151,0))) -> -0.0151 | J11: =IF($H$11=1,-0.3605,IF($H$11=2,-0.096,IF($H$11=3,-0.5516,0))) -> -0.5516 | K11: =IF($H$11=1,150.9,IF($H$11=2,237.86,IF($H$11=3,356.8,0))) -> 356.8 | L11: =IF($H$11=1,0.7,IF($H$11=2,0.094,IF($H$11=3,0.72,0))) -> 0.72 | M11: =IF($H$11=1,0.39,IF($H$11=2,0.85,IF($H$11=3,0.55,0))) -> 0.55 | N11: =IF($H$11 = 1, 83.7, IF($H$11 = 2, 245.7, IF($H$11 = 3, 136.5, 0))) -> 136.5 | AA11: Batteries | AB11: y | AC11: 1
B12: Loss coefficient Storage to House | C12: K | D12: 10
B13: Pressure from storage | C13: rho g h | D13: ='Flow Rate'!$F$18 -> 255060 | E13: Pa | G13: %0.0-0.3 | H13: Amount of Non-Potable Water per Day (L) | I13: Amount of Non-Potable Water per Day (m^3) | J13: Days of Non-Potable Water
B14: Consumption | C14: C | D14: 745 | E14: L/day | F14: Non-Potable Water | G14: 0.2 | H14: =(G14*D14) -> 149 | I14: =H14/1000 -> 0.149
A16: Weather Data Testing | B16: Starting month # | C16: Day | D16: Daily rainfall (mm) | E16: Q_in [m^3/day] | F16: V_water [m^3] | G16: Q_out [m^3/day] | H16: Pump Pressure | I16: Pump Energy | J16: Pump Energy | K16: Mass O3 | L16: Mass O3 | M16: Energy for O3 | N16: Energy for O3 | O16: Energy for UV | P16: Energy for UV | Q16: Total Energy for Day | R16: Diesel Fuel | S16: Total Diesel Fuel | T16: Matience for Liters of Fuel Used | U16: Hours of Diesel running | W16: Mass Chlorine | X16: Mass Chlorine | Y16: Cholrine used | Z16: Chlorine Maintinence
C17: [-] | D17: [-] | H17: [Pa] | I17: [J] | J17: [MJ] | K17: [mg] | L17: [g] | M17: [J] | N17: [MJ] | O17: [Wh] | P17: [MJ] | Q17: [MJ] | R17: [L] | S17: [L] | T17: Every 100L | W17: [mg] | X17: [kg] | Y17: [kg] | Z17: [-]
C18: 1 | D18: 18.8 | E18: =(D18/1000)*$J$7 -> 20.68 | F18: ='Studio Rain System'!L23 -> 20.68 | G18: ='Studio Rain System'!M23 -> 0 | H18: ='Flow Rate'!$W$27 -> 464206.53 | I18: ='Ozone-Energy'!H11 -> 3710582.9 | J18: =I18 * 10^(-6) -> 3.7105829 | K18: ='Ozone-Energy'!J11 -> 103400 | L18: =K18/1000 -> 103.4 | M18: ='Ozone-Energy'!L11 -> 0 | N18: ='Ozone-Energy'!M11 -> 0 | O18: ='Ozone-Energy'!N11 -> 1200 | P18: =O18 * 3600 / 1000000 -> 4.32 | Q18: =J18 + N18 + P18 -> 8.0305829 | R18: ='Ozone-Energy'!Q11 -> 0 | S18: ='Ozone-Energy'!R11 -> 0 | T18: ='Ozone-Energy'!S11 -> 0 | W18: ='Ozone-Energy'!V11 -> 0 | X18: ='Ozone-Energy'!W11 -> 0 | Y18: ='Ozone-Energy'!X11 -> 0 | Z18: ='Ozone-Energy'!Y11 -> 0
C19: 2 | D19: 19.8 | E19: =(D19/1000)*$J$7 -> 21.78 | F19: ='Studio Rain System'!L24 -> 20 | G19: ='Studio Rain System'!M24 -> 0 | H19: ='Flow Rate'!$W$27 -> 464206.53 | I19: ='Ozone-Energy'!H12 -> 3907954.3 | J19: =I19 * 10^(-6) -> 3.9079543 | K19: ='Ozone-Energy'!J12 -> 108900 | L19: =K19/1000 -> 108.9 | M19: ='Ozone-Energy'!L12 -> 0 | N19: ='Ozone-Energy'!M12 -> 0 | O19: ='Ozone-Energy'!N12 -> 1200 | P19: =O19 * 3600 / 1000000 -> 4.32 | Q19: =J19 + N19 + P19 -> 8.2279543 | R19: ='Ozone-Energy'!Q12 -> 0 | S19: ='Ozone-Energy'!R12 -> 0 | T19: ='Ozone-Energy'!S12 -> 0 | W19: ='Ozone-Energy'!V12 -> 0 | X19: ='Ozone-Energy'!W12 -> 0 | Y19: ='Ozone-Energy'!X12 -> 0 | Z19: ='Ozone-Energy'!Y12 -> 0
C20: 3 | D20: 0 | E20: =(D20/1000)*$J$7 -> 0 | F20: ='Studio Rain System'!L25 -> 20 | G20: ='Studio Rain System'!M25 -> 0 | H20: ='Flow Rate'!$W$27 -> 464206.53 | I20: ='Ozone-Energy'!H13 -> 0 | J20: =I20 * 10^(-6) -> 0 | K20: ='Ozone-Energy'!J13 -> 0 | L20: =K20/1000 -> 0 | M20: ='Ozone-Energy'!L13 -> 0 | N20: ='Ozone-Energy'!M13 -> 0 | O20: ='Ozone-Energy'!N13 -> 1200 | P20: =O20 * 3600 / 1000000 -> 4.32 | Q20: =J20 + N20 + P20 -> 4.32 | R20: ='Ozone-Energy'!Q13 -> 0 | S20: ='Ozone-Energy'!R13 -> 0 | T20: ='Ozone-Energy'!S13 -> 0 | W20: ='Ozone-Energy'!V13 -> 0 | X20: ='Ozone-Energy'!W13 -> 0 | Y20: ='Ozone-Energy'!X13 -> 0 | Z20: ='Ozone-Energy'!Y13 -> 0
C21: 4 | D21: 0 | E21: =(D21/1000)*$J$7 -> 0 | F21: ='Studio Rain System'!L26 -> 20 | G21: ='Studio Rain System'!M26 -> 0 | H21: ='Flow Rate'!$W$27 -> 464206.53 | I21: ='Ozone-Energy'!H14 -> 0 | J21: =I21 * 10^(-6) -> 0 | K21: ='Ozone-Energy'!J14 -> 0 | L21: =K21/1000 -> 0 | M21: ='Ozone-Energy'!L14 -> 0 | N21: ='Ozone-Energy'!M14 -> 0 | O21: ='Ozone-Energy'!N14 -> 1200 | P21: =O21 * 3600 / 1000000 -> 4.32 | Q21: =J21 + N21 + P21 -> 4.32 | R21: ='Ozone-Energy'!Q14 -> 0 | S21: ='Ozone-Energy'!R14 -> 0 | T21: ='Ozone-Energy'!S14 -> 0 | W21: ='Ozone-Energy'!V14 -> 0 | X21: ='Ozone-Energy'!W14 -> 0 | Y21: ='Ozone-Energy'!X14 -> 0 | Z21: ='Ozone-Energy'!Y14 -> 0
C22: 5 | D22: 0 | E22: =(D22/1000)*$J$7 -> 0 | F22: ='Studio Rain System'!L27 -> 20 | G22: ='Studio Rain System'!M27 -> 0 | H22: ='Flow Rate'!$W$27 -> 464206.53 | I22: ='Ozone-Energy'!H15 -> 0 | J22: =I22 * 10^(-6) -> 0 | K22: ='Ozone-Energy'!J15 -> 0 | L22: =K22/1000 -> 0 | M22: ='Ozone-Energy'!L15 -> 0 | N22: ='Ozone-Energy'!M15 -> 0 | O22: ='Ozone-Energy'!N15 -> 1200 | P22: =O22 * 3600 / 1000000 -> 4.32 | Q22: =J22 + N22 + P22 -> 4.32 | R22: ='Ozone-Energy'!Q15 -> 0 | S22: ='Ozone-Energy'!R15 -> 0 | T22: ='Ozone-Energy'!S15 -> 0 | W22: ='Ozone-Energy'!V15 -> 0 | X22: ='Ozone-Energy'!W15 -> 0 | Y22: ='Ozone-Energy'!X15 -> 0 | Z22: ='Ozone-Energy'!Y15 -> 0
C23: 6 | D23: 5 | E23: =(D23/1000)*$J$7 -> 5.5 | F23: ='Studio Rain System'!L28 -> 20 | G23: ='Studio Rain System'!M28 -> 0 | H23: ='Flow Rate'!$W$27 -> 464206.53 | I23: ='Ozone-Energy'!H16 -> 986857.14 | J23: =I23 * 10^(-6) -> 0.98685714 | K23: ='Ozone-Energy'!J16 -> 27500 | L23: =K23/1000 -> 27.5 | M23: ='Ozone-Energy'!L16 -> 0 | N23: ='Ozone-Energy'!M16 -> 0 | O23: ='Ozone-Energy'!N16 -> 1200 | P23: =O23 * 3600 / 1000000 -> 4.32 | Q23: =J23 + N23 + P23 -> 5.3068571 | R23: ='Ozone-Energy'!Q16 -> 0 | S23: ='Ozone-Energy'!R16 -> 0 | T23: ='Ozone-Energy'!S16 -> 0 | W23: ='Ozone-Energy'!V16 -> 0 | X23: ='Ozone-Energy'!W16 -> 0 | Y23: ='Ozone-Energy'!X16 -> 0 | Z23: ='Ozone-Energy'!Y16 -> 0
C24: 7 | D24: 20.4 | E24: =(D24/1000)*$J$7 -> 22.44 | F24: ='Studio Rain System'!L29 -> 20 | G24: ='Studio Rain System'!M29 -> 0 | H24: ='Flow Rate'!$W$27 -> 464206.53 | I24: ='Ozone-Energy'!H17 -> 4026377.1 | J24: =I24 * 10^(-6) -> 4.0263771 | K24: ='Ozone-Energy'!J17 -> 112200 | L24: =K24/1000 -> 112.2 | M24: ='Ozone-Energy'!L17 -> 0 | N24: ='Ozone-Energy'!M17 -> 0 | O24: ='Ozone-Energy'!N17 -> 1200 | P24: =O24 * 3600 / 1000000 -> 4.32 | Q24: =J24 + N24 + P24 -> 8.3463771 | R24: ='Ozone-Energy'!Q17 -> 0 | S24: ='Ozone-Energy'!R17 -> 0 | T24: ='Ozone-Energy'!S17 -> 0 | W24: ='Ozone-Energy'!V17 -> 0 | X24: ='Ozone-Energy'!W17 -> 0 | Y24: ='Ozone-Energy'!X17 -> 0 | Z24: ='Ozone-Energy'!Y17 -> 0
C25: 8 | D25: 24.8 | E25: =(D25/1000)*$J$7 -> 27.28 | F25: ='Studio Rain System'!L30 -> 20 | G25: ='Studio Rain System'!M30 -> 0 | H25: ='Flow Rate'!$W$27 -> 464206.53 | I25: ='Ozone-Energy'!H18 -> 4894811.4 | J25: =I25 * 10^(-6) -> 4.8948114 | K25: ='Ozone-Energy'!J18 -> 136400 | L25: =K25/1000 -> 136.4 | M25: ='Ozone-Energy'!L18 -> 0 | N25: ='Ozone-Energy'!M18 -> 0 | O25: ='Ozone-Energy'!N18 -> 1200 | P25: =O25 * 3600 / 1000000 -> 4.32 | Q25: =J25 + N25 + P25 -> 9.2148114 | R25: ='Ozone-Energy'!Q18 -> 0 | S25: ='Ozone-Energy'!R18 -> 0 | T25: ='Ozone-Energy'!S18 -> 0 | W25: ='Ozone-Energy'!V18 -> 0 | X25: ='Ozone-Energy'!W18 -> 0 | Y25: ='Ozone-Energy'!X18 -> 0 | Z25: ='Ozone-Energy'!Y18 -> 0
C26: 9 | D26: 34 | E26: =(D26/1000)*$J$7 -> 37.4 | F26: ='Studio Rain System'!L31 -> 20 | G26: ='Studio Rain System'!M31 -> 0 | H26: ='Flow Rate'!$W$27 -> 464206.53 | I26: ='Ozone-Energy'!H19 -> 6710628.6 | J26: =I26 * 10^(-6) -> 6.7106286 | K26: ='Ozone-Energy'!J19 -> 187000 | L26: =K26/1000 -> 187 | M26: ='Ozone-Energy'!L19 -> 0 | N26: ='Ozone-Energy'!M19 -> 0 | O26: ='Ozone-Energy'!N19 -> 1200 | P26: =O26 * 3600 / 1000000 -> 4.32 | Q26: =J26 + N26 + P26 -> 11.030629 | R26: ='Ozone-Energy'!Q19 -> 0 | S26: ='Ozone-Energy'!R19 -> 0 | T26: ='Ozone-Energy'!S19 -> 0 | W26: ='Ozone-Energy'!V19 -> 0 | X26: ='Ozone-Energy'!W19 -> 0 | Y26: ='Ozone-Energy'!X19 -> 0 | Z26: ='Ozone-Energy'!Y19 -> 0
C27: 10 | D27: 44.6 | E27: =(D27/1000)*$J$7 -> 49.06 | F27: ='Studio Rain System'!L32 -> 20 | G27: ='Studio Rain System'!M32 -> 0 | H27: ='Flow Rate'!$W$27 -> 464206.53 | I27: ='Ozone-Energy'!H20 -> 8802765.7 | J27: =I27 * 10^(-6) -> 8.8027657 | K27: ='Ozone-Energy'!J20 -> 245300 | L27: =K27/1000 -> 245.3 | M27: ='Ozone-Energy'!L20 -> 0 | N27: ='Ozone-Energy'!M20 -> 0 | O27: ='Ozone-Energy'!N20 -> 1200 | P27: =O27 * 3600 / 1000000 -> 4.32 | Q27: =J27 + N27 + P27 -> 13.122766 | R27: ='Ozone-Energy'!Q20 -> 0 | S27: ='Ozone-Energy'!R20 -> 0 | T27: ='Ozone-Energy'!S20 -> 0 | W27: ='Ozone-Energy'!V20 -> 0 | X27: ='Ozone-Energy'!W20 -> 0 | Y27: ='Ozone-Energy'!X20 -> 0 | Z27: ='Ozone-Energy'!Y20 -> 0
C28: 11 | D28: 14.4 | E28: =(D28/1000)*$J$7 -> 15.84 | F28: ='Studio Rain System'!L33 -> 20 | G28: ='Studio Rain System'!M33 -> 0 | H28: ='Flow Rate'!$W$27 -> 464206.53 | I28: ='Ozone-Energy'!H21 -> 2842148.6 | J28: =I28 * 10^(-6) -> 2.8421486 | K28: ='Ozone-Energy'!J21 -> 79200 | L28: =K28/1000 -> 79.2 | M28: ='Ozone-Energy'!L21 -> 0 | N28: ='Ozone-Energy'!M21 -> 0 | O28: ='Ozone-Energy'!N21 -> 1200 | P28: =O28 * 3600 / 1000000 -> 4.32 | Q28: =J28 + N28 + P28 -> 7.1621486 | R28: ='Ozone-Energy'!Q21 -> 0 | S28: ='Ozone-Energy'!R21 -> 0 | T28: ='Ozone-Energy'!S21 -> 0 | W28: ='Ozone-Energy'!V21 -> 0 | X28: ='Ozone-Energy'!W21 -> 0 | Y28: ='Ozone-Energy'!X21 -> 0 | Z28: ='Ozone-Energy'!Y21 -> 0
C29: 12 | D29: 50.2 | E29: =(D29/1000)*$J$7 -> 55.22 | F29: ='Studio Rain System'!L34 -> 20 | G29: ='Studio Rain System'!M34 -> 0 | H29: ='Flow Rate'!$W$27 -> 464206.53 | I29: ='Ozone-Energy'!H22 -> 9908045.7 | J29: =I29 * 10^(-6) -> 9.9080457 | K29: ='Ozone-Energy'!J22 -> 276100 | L29: =K29/1000 -> 276.1 | M29: ='Ozone-Energy'!L22 -> 0 | N29: ='Ozone-Energy'!M22 -> 0 | O29: ='Ozone-Energy'!N22 -> 1200 | P29: =O29 * 3600 / 1000000 -> 4.32 | Q29: =J29 + N29 + P29 -> 14.228046 | R29: ='Ozone-Energy'!Q22 -> 0 | S29: ='Ozone-Energy'!R22 -> 0 | T29: ='Ozone-Energy'!S22 -> 0 | W29: ='Ozone-Energy'!V22 -> 0 | X29: ='Ozone-Energy'!W22 -> 0 | Y29: ='Ozone-Energy'!X22 -> 0 | Z29: ='Ozone-Energy'!Y22 -> 0
... C57: 40 | D57: 12.2 | E57: =(D57/1000)*$J$7 -> 13.42 | F57: ='Studio Rain System'!L62 -> 20 | G57: ='Studio Rain System'!M62 -> 0.745 | H57: ='Flow Rate'!$W$27 -> 464206.53 | I57: ='Ozone-Energy'!H50 -> 2407931.4 | J57: =I57 * 10^(-6) -> 2.4079314 | K57: ='Ozone-Energy'!J50 -> 67100 | L57: =K57/1000 -> 67.1 | M57: ='Ozone-Energy'!L50 -> 1.342e+08 | N57: ='Ozone-Energy'!M50 -> 134.2 | O57: ='Ozone-Energy'!N50 -> 1200 | P57: =O57 * 3600 / 1000000 -> 4.32 | Q57: =J57 + N57 + P57 -> 140.92793 | R57: ='Ozone-Energy'!Q50 -> 0 | S57: ='Ozone-Energy'!R50 -> 0 | T57: ='Ozone-Energy'!S50 -> 0 | W57: ='Ozone-Energy'!V50 -> 0 | X57: ='Ozone-Energy'!W50 -> 0 | Y57: ='Ozone-Energy'!X50 -> 0 | Z57: ='Ozone-Energy'!Y50 -> 0
C58: 41 | D58: 13.4 | E58: =(D58/1000)*$J$7 -> 14.74 | F58: ='Studio Rain System'!L63 -> 20 | G58: ='Studio Rain System'!M63 -> 0.745 | H58: ='Flow Rate'!$W$27 -> 464206.53 | I58: ='Ozone-Energy'!H51 -> 2644777.1 | J58: =I58 * 10^(-6) -> 2.6447771 | K58: ='Ozone-Energy'!J51 -> 73700 | L58: =K58/1000 -> 73.7 | M58: ='Ozone-Energy'!L51 -> 147400000 | N58: ='Ozone-Energy'!M51 -> 147.4 | O58: ='Ozone-Energy'!N51 -> 1200 | P58: =O58 * 3600 / 1000000 -> 4.32 | Q58: =(J58 + N58 + P58) -> 154.36478 | R58: ='Ozone-Energy'!Q51 -> 0 | S58: ='Ozone-Energy'!R51 -> 0 | T58: ='Ozone-Energy'!S51 -> 0 | W58: ='Ozone-Energy'!V51 -> 0 | X58: ='Ozone-Energy'!W51 -> 0 | Y58: ='Ozone-Energy'!X51 -> 0 | Z58: ='Ozone-Energy'!Y51 -> 0
C59: 42 | D59: 46.6 | E59: =(D59/1000)*$J$7 -> 51.26 | F59: ='Studio Rain System'!L64 -> 20 | G59: ='Studio Rain System'!M64 -> 0.745 | H59: ='Flow Rate'!$W$27 -> 464206.53 | I59: ='Ozone-Energy'!H52 -> 9197508.6 | J59: =I59 * 10^(-6) -> 9.1975086 | K59: ='Ozone-Energy'!J52 -> 256300 | L59: =K59/1000 -> 256.3 | M59: ='Ozone-Energy'!L52 -> 5.126e+08 | N59: ='Ozone-Energy'!M52 -> 512.6 | O59: ='Ozone-Energy'!N52 -> 1200 | P59: =O59 * 3600 / 1000000 -> 4.32 | Q59: =J59 + N59 + P59 -> 526.11751 | R59: ='Ozone-Energy'!Q52 -> 0 | S59: ='Ozone-Energy'!R52 -> 0 | T59: ='Ozone-Energy'!S52 -> 0 | W59: ='Ozone-Energy'!V52 -> 0 | X59: ='Ozone-Energy'!W52 -> 0 | Y59: ='Ozone-Energy'!X52 -> 0 | Z59: ='Ozone-Energy'!Y52 -> 0
C60: 43 | D60: 16.8 | E60: =(D60/1000)*$J$7 -> 18.48 | F60: ='Studio Rain System'!L65 -> 20 | G60: ='Studio Rain System'!M65 -> 0.745 | H60: ='Flow Rate'!$W$27 -> 464206.53 | I60: ='Ozone-Energy'!H53 -> 3315840 | J60: =I60 * 10^(-6) -> 3.31584 | K60: ='Ozone-Energy'!J53 -> 92400 | L60: =K60/1000 -> 92.4 | M60: ='Ozone-Energy'!L53 -> 1.848e+08 | N60: ='Ozone-Energy'!M53 -> 184.8 | O60: ='Ozone-Energy'!N53 -> 1200 | P60: =O60 * 3600 / 1000000 -> 4.32 | Q60: =J60 + N60 + P60 -> 192.43584 | R60: ='Ozone-Energy'!Q53 -> 0 | S60: ='Ozone-Energy'!R53 -> 0 | T60: ='Ozone-Energy'!S53 -> 0 | W60: ='Ozone-Energy'!V53 -> 0 | X60: ='Ozone-Energy'!W53 -> 0 | Y60: ='Ozone-Energy'!X53 -> 0 | Z60: ='Ozone-Energy'!Y53 -> 0
C61: 44 | D61: 15.6 | E61: =(D61/1000)*$J$7 -> 17.16 | F61: ='Studio Rain System'!L66 -> 20 | G61: ='Studio Rain System'!M66 -> 0.745 | H61: ='Flow Rate'!$W$27 -> 464206.53 | I61: ='Ozone-Energy'!H54 -> 3078994.3 | J61: =I61 * 10^(-6) -> 3.0789943 | K61: ='Ozone-Energy'!J54 -> 85800 | L61: =K61/1000 -> 85.8 | M61: ='Ozone-Energy'!L54 -> 171600000 | N61: ='Ozone-Energy'!M54 -> 171.6 | O61: ='Ozone-Energy'!N54 -> 1200 | P61: =O61 * 3600 / 1000000 -> 4.32 | Q61: =J61 + N61 + P61 -> 178.99899 | R61: ='Ozone-Energy'!Q54 -> 0 | S61: ='Ozone-Energy'!R54 -> 0 | T61: ='Ozone-Energy'!S54 -> 0 | W61: ='Ozone-Energy'!V54 -> 0 | X61: ='Ozone-Energy'!W54 -> 0 | Y61: ='Ozone-Energy'!X54 -> 0 | Z61: ='Ozone-Energy'!Y54 -> 0
C62: 45 | D62: 3 | E62: =(D62/1000)*$J$7 -> 3.3 | F62: ='Studio Rain System'!L67 -> 20 | G62: ='Studio Rain System'!M67 -> 0.745 | H62: ='Flow Rate'!$W$27 -> 464206.53 | I62: ='Ozone-Energy'!H55 -> 592114.29 | J62: =I62 * 10^(-6) -> 0.59211429 | K62: ='Ozone-Energy'!J55 -> 16500 | L62: =K62/1000 -> 16.5 | M62: ='Ozone-Energy'!L55 -> 33000000 | N62: ='Ozone-Energy'!M55 -> 33 | O62: ='Ozone-Energy'!N55 -> 1200 | P62: =O62 * 3600 / 1000000 -> 4.32 | Q62: =J62 + N62 + P62 -> 37.912114 | R62: ='Ozone-Energy'!Q55 -> 0 | S62: ='Ozone-Energy'!R55 -> 0 | T62: ='Ozone-Energy'!S55 -> 0 | W62: ='Ozone-Energy'!V55 -> 0 | X62: ='Ozone-Energy'!W55 -> 0 | Y62: ='Ozone-Energy'!X55 -> 0 | Z62: ='Ozone-Energy'!Y55 -> 0
C63: 46 | D63: 11.6 | E63: =(D63/1000)*$J$7 -> 12.76 | F63: ='Studio Rain System'!L68 -> 20 | G63: ='Studio Rain System'!M68 -> 0.745 | H63: ='Flow Rate'!$W$27 -> 464206.53 | I63: ='Ozone-Energy'!H56 -> 2289508.6 | J63: =I63 * 10^(-6) -> 2.2895086 | K63: ='Ozone-Energy'!J56 -> 63800 | L63: =K63/1000 -> 63.8 | M63: ='Ozone-Energy'!L56 -> 127600000 | N63: ='Ozone-Energy'!M56 -> 127.6 | O63: ='Ozone-Energy'!N56 -> 1200 | P63: =O63 * 3600 / 1000000 -> 4.32 | Q63: =J63 + N63 + P63 -> 134.20951 | R63: ='Ozone-Energy'!Q56 -> 0 | S63: ='Ozone-Energy'!R56 -> 0 | T63: ='Ozone-Energy'!S56 -> 0 | W63: ='Ozone-Energy'!V56 -> 0 | X63: ='Ozone-Energy'!W56 -> 0 | Y63: ='Ozone-Energy'!X56 -> 0 | Z63: ='Ozone-Energy'!Y56 -> 0
C64: 47 | D64: 19 | E64: =(D64/1000)*$J$7 -> 20.9 | F64: ='Studio Rain System'!L69 -> 20 | G64: ='Studio Rain System'!M69 -> 0.745 | H64: ='Flow Rate'!$W$27 -> 464206.53 | I64: ='Ozone-Energy'!H57 -> 3750057.1 | J64: =I64 * 10^(-6) -> 3.7500571 | K64: ='Ozone-Energy'!J57 -> 104500 | L64: =K64/1000 -> 104.5 | M64: ='Ozone-Energy'!L57 -> 209000000 | N64: ='Ozone-Energy'!M57 -> 209 | O64: ='Ozone-Energy'!N57 -> 1200 | P64: =O64 * 3600 / 1000000 -> 4.32 | Q64: =J64 + N64 + P64 -> 217.07006 | R64: ='Ozone-Energy'!Q57 -> 0 | S64: ='Ozone-Energy'!R57 -> 0 | T64: ='Ozone-Energy'!S57 -> 0 | W64: ='Ozone-Energy'!V57 -> 0 | X64: ='Ozone-Energy'!W57 -> 0 | Y64: ='Ozone-Energy'!X57 -> 0 | Z64: ='Ozone-Energy'!Y57 -> 0
C65: 48 | D65: 9.2 | E65: =(D65/1000)*$J$7 -> 10.12 | F65: ='Studio Rain System'!L70 -> 20 | G65: ='Studio Rain System'!M70 -> 0.745 | H65: ='Flow Rate'!$W$27 -> 464206.53 | I65: ='Ozone-Energy'!H58 -> 1815817.1 | J65: =I65 * 10^(-6) -> 1.8158171 | K65: ='Ozone-Energy'!J58 -> 50600 | L65: =K65/1000 -> 50.6 | M65: ='Ozone-Energy'!L58 -> 101200000 | N65: ='Ozone-Energy'!M58 -> 101.2 | O65: ='Ozone-Energy'!N58 -> 1200 | P65: =O65 * 3600 / 1000000 -> 4.32 | Q65: =J65 + N65 + P65 -> 107.33582 | R65: ='Ozone-Energy'!Q58 -> 0 | S65: ='Ozone-Energy'!R58 -> 0 | T65: ='Ozone-Energy'!S58 -> 0 | W65: ='Ozone-Energy'!V58 -> 0 | X65: ='Ozone-Energy'!W58 -> 0 | Y65: ='Ozone-Energy'!X58 -> 0 | Z65: ='Ozone-Energy'!Y58 -> 0
C66: 49 | D66: 12.6 | E66: =(D66/1000)*$J$7 -> 13.86 | F66: ='Studio Rain System'!L71 -> 20 | G66: ='Studio Rain System'!M71 -> 0.745 | H66: ='Flow Rate'!$W$27 -> 464206.53 | I66: ='Ozone-Energy'!H59 -> 2486880 | J66: =I66 * 10^(-6) -> 2.48688 | K66: ='Ozone-Energy'!J59 -> 69300 | L66: =K66/1000 -> 69.3 | M66: ='Ozone-Energy'!L59 -> 138600000 | N66: ='Ozone-Energy'!M59 -> 138.6 | O66: ='Ozone-Energy'!N59 -> 1200 | P66: =O66 * 3600 / 1000000 -> 4.32 | Q66: =J66 + N66 + P66 -> 145.40688 | R66: ='Ozone-Energy'!Q59 -> 0 | S66: ='Ozone-Energy'!R59 -> 0 | T66: ='Ozone-Energy'!S59 -> 0 | W66: ='Ozone-Energy'!V59 -> 0 | X66: ='Ozone-Energy'!W59 -> 0 | Y66: ='Ozone-Energy'!X59 -> 0 | Z66: ='Ozone-Energy'!Y59 -> 0
C67: 50 | D67: 21.8 | E67: =(D67/1000)*$J$7 -> 23.98 | F67: ='Studio Rain System'!L72 -> 20 | G67: ='Studio Rain System'!M72 -> 0.745 | H67: ='Flow Rate'!$W$27 -> 464206.53 | I67: ='Ozone-Energy'!H60 -> 4302697.1 | J67: =I67 * 10^(-6) -> 4.3026971 | K67: ='Ozone-Energy'!J60 -> 119900 | L67: =K67/1000 -> 119.9 | M67: ='Ozone-Energy'!L60 -> 239800000 | N67: ='Ozone-Energy'!M60 -> 239.8 | O67: ='Ozone-Energy'!N60 -> 1200 | P67: =O67 * 3600 / 1000000 -> 4.32 | Q67: =J67 + N67 + P67 -> 248.4227 | R67: ='Ozone-Energy'!Q60 -> 0 | S67: ='Ozone-Energy'!R60 -> 0 | T67: ='Ozone-Energy'!S60 -> 0 | W67: ='Ozone-Energy'!V60 -> 0 | X67: ='Ozone-Energy'!W60 -> 0 | Y67: ='Ozone-Energy'!X60 -> 0 | Z67: ='Ozone-Energy'!Y60 -> 0
C68: 51 | D68: 2.4 | E68: =(D68/1000)*$J$7 -> 2.64 | F68: ='Studio Rain System'!L73 -> 20 | G68: ='Studio Rain System'!M73 -> 0.745 | H68: ='Flow Rate'!$W$27 -> 464206.53 | I68: ='Ozone-Energy'!H61 -> 473691.43 | J68: =I68 * 10^(-6) -> 0.47369143 | K68: ='Ozone-Energy'!J61 -> 13200 | L68: =K68/1000 -> 13.2 | M68: ='Ozone-Energy'!L61 -> 26400000 | N68: ='Ozone-Energy'!M61 -> 26.4 | O68: ='Ozone-Energy'!N61 -> 1200 | P68: =O68 * 3600 / 1000000 -> 4.32 | Q68: =J68 + N68 + P68 -> 31.193691 | R68: ='Ozone-Energy'!Q61 -> 0 | S68: ='Ozone-Energy'!R61 -> 0 | T68: ='Ozone-Energy'!S61 -> 0 | W68: ='Ozone-Energy'!V61 -> 0 | X68: ='Ozone-Energy'!W61 -> 0 | Y68: ='Ozone-Energy'!X61 -> 0 | Z68: ='Ozone-Energy'!Y61 -> 0
...

Sheet Stakeholder Satisfaction
A1: RWH Satisfaction Values | C1: RED IS INPUT ONLY, TYPE NEW VALUES INTO RED
A2: Team J-9
A4: Satisfaction Curve Data from Compnent Selection Guide
A6: Attribute | B6: Parameter | C6: Equation | D6: Value | E6: Weight | F6: Min Value | G6: Max. Value | H6: Units | I6: Satisfaction | J6: Weight | K6: Weighted percents
A7: Consumption, C | B7: C | D7: ='Studio Rain System'!B11 -> 745 | E7: H | F7: 125 | G7: 745 | H7: L/day | I7: =IF(D7 > G7, 1, IF(D7<F7, 0,0.5*(1-COS((($D7-$F7)/($G7-$F7))*PI())))) -> 1 | J7: =H18*3 -> 0.1875 | K7: =I7*J7 -> 0.1875
A8: Relative cost, C_R | B8: C_R | D8: =Costs!B64 -> 54218.769 | E8: H | F8: =0.3*110000 -> 33000 | G8: =1.15*110000 -> 126500 | H8: % relative to shipping water | I8: =IF(D8<F8, 1, IF(D8>G8, 0, 0.5*(1+COS((($D8-F8)/(G8-F8))*PI())))) -> 0.87821817 | J8: =H18*3 -> 0.1875 | K8: =I8*J8 -> 0.16466591
A9: Health & environmental risk exposure, E | B9: E | D9: ='Health & Environment'!$AM$11 -> 0 | E9: M | F9: 1 | G9: 24 | H9: N/A | I9: =IF(D9 < F9, 1, IF(D9>G9, 0, 0.5*(1+COS(($D9-$F9)/($G9-$F9)*PI())))) -> 1 | J9: =$H$18*2 -> 0.125 | K9: =I9*J9 -> 0.125
A10: Power System & Greenhouse Gas, G | B10: G | D10: ='Greenhouse Gases'!G10 -> 34.662561 | E10: M | F10: 15 | G10: 110 | H10: % relative to shipping water | I10: =IF(D10<F10, 1, IF(D10>G10, 0, 0.5*(1+COS(($D10-$F10)/($G10-$F10)*PI())))) -> 0.89797258 | J10: =$H$18*2 -> 0.125 | K10: =I10*J10 -> 0.11224657
A11: Maintenance Occurence, MP | B11: M | D11: ='Organized Input Output'!I4 -> 18 | E11: M | F11: 10 | G11: 60 | H11: #/year | I11: =IF(D11<F11, 1, IF(D11>G11, 0, 0.5*(1+COS(($D11-$F11)/($G11-$F11)*PI())))) -> 0.93815334 | J11: =$H$18*2 -> 0.125 | K11: =I11*J11 -> 0.11726917
A12: Non-potable water supply, NP | B12: NP | D12: ='Organized Input Output'!G14 -> 0.2 | E12: L | F12: 0 | G12: 0.3 | H12: Average L/day (as fraction of consumption, C) | I12: =IF(D12>G12, 1, 0.5*(1-COS(($D12-$F12)/($G12-$F12)*PI()))) -> 0.75 | J12: =$H$18*1 -> 0.0625 | K12: =I12*J12 -> 0.046875
A13: On-demand flow rate, Qin | B13: Qin | D13: ='Organized Input Output'!Q4 -> 41.469023 | E13: L | F13: 18 | G13: 40 | H13: L/min | I13: =IF(D13>G13, 1, IF(D13<F13, 0, 0.5*(1-COS(($D13-$F13)/($G13-$F13)*PI())))) -> 1 | J13: =$H$18*1 -> 0.0625 | K13: =I13*J13 -> 0.0625
A14: Reliability (days consumption met), R | B14: R | D14: =(365-'Studio Rain System'!G13) -> 356 | E14: M | F14: 200 | G14: 365 | H14: days/year | I14: =IF(D14<F14, 0, 0.5*(1-COS(($D14-$F14)/($G14-$F14)*PI()))) -> 0.99267692 | J14: =$H$18*2 -> 0.125 | K14: =I14*J14 -> 0.12408461
A15: Overall Satisfaction | I15: =AVERAGE(I7:I14) -> 0.93212763 | J15: =SUM(J7:J14) -> 1 | K15: =SUM(K7:K14) -> 0.94014126
H18: 0.0625

Sheet Costs
A1: RWH Input-Output Data
A2: Team J-9
A3: Costs
A5: Description | B5: Input | C5: Item Cost | D5: Cost
A6: Catchment Area
A7: half roof catchment | B7: 0 | C7: 150 | D7: =C7*B7 -> 0
A8: full roof catchment | B8: =IF('Organized Input Output'!$H$7 = 100, 1, 0) -> 1 | C8: 350 | D8: =C8*B8 -> 350
A9: additional catchment | B9: ='Organized Input Output'!$I$7 -> 1000 | C9: 500+10/m3 | D9: =IF(B9 = 0, 0, 500+10*B9) -> 10500
A11: Catchment tank
A12: 400L | B12: =IF('Organized Input Output'!$K$7 = 400, 1, 0) -> 0 | C12: 200 | D12: =C12*B12 -> 0
A13: 1500L | B13: =IF('Organized Input Output'!$K$7 = 1500, 1, 0) -> 0 | C13: 500 | D13: =C13*B13 -> 0
A14: 2500L | B14: =IF('Organized Input Output'!$K$7 = 2500, 1, 0) -> 1 | C14: 900 | D14: =C14*B14 -> 900
A15: 5000L | B15: =IF('Organized Input Output'!$K$7 = 5000, 1, 0) -> 0 | C15: 1500 | D15: =C15*B15 -> 0
A16: 10000L | B16: =IF('Organized Input Output'!$K$7 = 10000, 1, 0) -> 0 | C16: 2000 | D16: =C16*B16 -> 0
A18: Storage Tank
A19: Volume | B19: ='Organized Input Output'!$H$9 -> 20 | C19: 300/m3 | D19: =300*B19 -> 6000
A20: Water level Sensor | B20: 1 | C20: 250 | D20: =C20*B20 -> 250
A21: Storage Tank Tower | B21: ='Organized Input Output'!$M$9 -> 21 | C21: 25(V_tank)^(1.6)+150(H_tower)^(1.8) | D21: =IF(B21 = 1, 25*(B19)^(1.6)+150*(B21)^(1.8), 0) -> 0
A22: Piping | B22: =SQRT(('Organized Input Output'!$I$9)^2+('Organized Input Output'!$J$9)^2+('Organized Input Output'!N9)^2) -> 48.74423 | C22: 40/m3 | D22: =40*B22 -> 1949.7692
A24: Water Treatment
A25: Bag Filter | B25: =IF('Organized Input Output'!R7 = "y", 1,0) -> 1 | C25: 100 | D25: =C25*B25 -> 100
A26: 1um Cartridge | B26: =IF('Organized Input Output'!R8 = "y", 1,0) -> 1 | C26: 110 | D26: =C26*B26 -> 110
A27: 5um Cartridge | B27: =IF('Organized Input Output'!R9 = "y", 1,0) -> 1 | C27: 125 | D27: =C27*B27 -> 125
A29: Chemical Disinfection
A31: Chlorine Initial | B31: =IF('Organized Input Output'!AD3 = "y", 1,0) -> 0 | C31: 700 | D31: =C31*B31 -> 0
A33: Ozone initial | B33: =IF('Organized Input Output'!AD5 = "y", 1, 0) -> 1 | C33: 4000 | D33: =C33*B33 -> 4000
A35: UV System
A36: 36W | B36: =IF('Organized Input Output'!AB4 = "y", 1,0) -> 0 | C36: 500 | D36: =C36*B36 -> 0
A37: 40W | B37: =IF('Organized Input Output'!AB5 = "y", 1, 0) -> 0 | C37: 600 | D37: =C37*B37 -> 0
A38: 50W | B38: =IF('Organized Input Output'!AB6 = "y", 1,0) -> 1 | C38: 850 | D38: =C38*B38 -> 850
A40: Pump Specs
A41: Pump A | B41: =IF( 'Organized Input Output'!$H$11 = 1, 1, 0) -> 0 | C41: 640 | D41: =C41*B41 -> 0
A42: Pump B | B42: =IF( 'Organized Input Output'!$H$11 = 2, 1, 0) -> 0 | C42: 1250 | D42: =C42*B42 -> 0
A43: Pump C | B43: =IF( 'Organized Input Output'!$H$11 = 3, 1, 0) -> 1 | C43: 3250 | D43: =C43*B43 -> 3250
A45: Power System
A46: Solar Panels
A47: HES-260 | B47: =IF('Organized Input Output'!$AA$9 = 260, 1, 0)*'Organized Input Output'!AC9 -> 0 | C47: 550 | D47: =C47*B47 -> 0
A48: SW-80 | B48: =IF('Organized Input Output'!$AA$9 = 80, 1, 0)*'Organized Input Output'!AC9 -> 5 | C48: 205 | D48: =C48*B48 -> 1025
A49: HES-306P | B49: =IF('Organized Input Output'!$AA$9 = 306, 1, 0)*'Organized Input Output'!AC9 -> 0 | C49: 450 | D49: =C49*B49 -> 0
A51: Diesel Generator | B51: =IF( 'Organized Input Output'!$AF$9 = "y", 1, 0) -> 0 | C51: 3250 | D51: =C51*B51 -> 0
...

Sheet Flow Rate
A1: RWH Input-Output Data
A2: Team J-9
A3: Distance to storage tank, L | B3: ='Organized Input Output'!K9 -> 41.533119 | C3: [m]
A4: Height of storage tank | B4: ='Organized Input Output'!N9 -> 26 | C4: [m]
A5: Density of water, ρ | B5: ='Organized Input Output'!D9 -> 1000 | C5: [kg/m3]
A6: Gravity constant, g | B6: ='Organized Input Output'!D6 -> 9.81 | C6: [m/s2]
A7: Pump coefficients a | B7: ='Organized Input Output'!I11 -> -0.0151
A8: Pump coefficients b | B8: ='Organized Input Output'!J11 -> -0.5516
A9: Pump coefficients c | B9: ='Organized Input Output'!K11 -> 356.8
A10: Diameter of pipe D | B10: ='Organized Input Output'!D7 -> 0.02 | C10: [m]
A11: Area of the pipe | B11: ='Organized Input Output'!D8 -> 0.00031415927 | C11: [m^2]
A12: Friction factor for pipe, f | B12: ='Organized Input Output'!D10 -> 0.05
A13: Loss coefficient due to fittings and valves on the pipe, K | B13: ='Organized Input Output'!D12 -> 10 | C13: [K] | D13: Storage to House | U13: House to Storage
A14: Filter coefficient, Cf | B14: ='Organized Input Output'!G4 -> 13743
D16: Flow Velocity, V | E16: Flow Rate, Q | F16: Pump Pressure, Pa | G16: System Curve Pressure, Pa | U16: Flow Velocity, V | V16: Flow Rate, Q | W16: Pump Pressure, Pa | X16: System Curve Pressure, Pa
D17: [m/s] | E17: [L/min] | F17: [Pa] | G17: [Pa] | H17: Q (m³/s) | I17: Difference from pump to system | U17: [m/s] | V17: [L/min] | W17: [Pa] | X17: [Pa] | Y17: Q (m³/s) | Z17: Difference from pump to system | AA17: Variable Efficiency
D18: 0 | E18: =(D18 * $B$11) * 60000 -> 0 | F18: =$B$5*$B$6*$B$4 -> 255060 | G18: =($B$12*($B$3/($B$10))*(($B$5*D18^2)/2))+($B$13*($B$5*D18^2)/2) -> 0 | H18: =E18 / 1000 / 60 -> 0 | I18: =F18-G18 -> 255060 | U18: 0 | V18: =(U18 * $B$11) * 60000 -> 0 | W18: =$B$5*$B$6*$B$4 + ($B$12*($B$3/$B$10)*($B$5*U18*U18/2)) + ($B$13*($B$5*U18*U18/2)) + $B$14*U18 -> 255060 | X18: =($B$7*(V18*V18) + $B$8*V18 + $B$9)*1000 -> 356800 | Y18: =V18 / 1000 / 60 -> 0 | Z18: =W18-X18 -> -101740 | AA18: =1.2*'Organized Input Output'!$L$11 * (EXP(V18/'Organized Input Output'!$N$11) - 1 - 1.72 * (V18 / 'Organized Input Output'!$N$11)^4 )^ 'Organized Input Output'!$M$11 -> 0
D19: =D18+0.2 -> 0.2 | E19: =(D19 * $B$11) * 60000 -> 3.7699112 | F19: =$B$5*$B$6*$B$4 -> 255060 | G19: =($B$12*($B$3/($B$10))*(($B$5*D19^2)/2))+($B$13*($B$5*D19^2)/2) -> 2276.656 | H19: =E19 / 1000 / 60 -> 6.2831853e-05 | I19: =F19-G19 -> 252783.34 | U19: =U18+0.2 -> 0.2 | V19: =(U19 * $B$11) * 60000 -> 3.7699112 | W19: =$B$5*$B$6*$B$4 + ($B$12*($B$3/$B$10)*($B$5*U19*U19/2)) + ($B$13*($B$5*U19*U19/2)) + $B$14*U19 -> 260085.26 | X19: =($B$7*(V19*V19) + $B$8*V19 + $B$9)*1000 -> 354505.91 | Y19: =V19 / 1000 / 60 -> 6.2831853e-05 | Z19: =W19-X19 -> -94420.656 | AA19: =1.2*'Organized Input Output'!$L$11 * (EXP(V19/'Organized Input Output'!$N$11) - 1 - 1.72 * (V19/'Organized Input Output'!$N$11)^4 )^ 'Organized Input Output'!$M$11 -> 0.12091229
D20: =D19+0.2 -> 0.4 | E20: =(D20 * $B$11) * 60000 -> 7.5398224 | F20: =$B$5*$B$6*$B$4 -> 255060 | G20: =($B$12*($B$3/($B$10))*(($B$5*D20^2)/2))+($B$13*($B$5*D20^2)/2) -> 9106.6239 | H20: =E20 / 1000 / 60 -> 0.00012566371 | I20: =F20-G20 -> 245953.38 | U20: =U19+0.2 -> 0.4 | V20: =(U20 * $B$11) * 60000 -> 7.5398224 | W20: =$B$5*$B$6*$B$4 + ($B$12*($B$3/$B$10)*($B$5*U20*U20/2)) + ($B$13*($B$5*U20*U20/2)) + $B$14*U20 -> 269663.82 | X20: =($B$7*(V20*V20) + $B$8*V20 + $B$9)*1000 -> 351782.62 | Y20: =V20 / 1000 / 60 -> 0.00012566371 | Z20: =W20-X20 -> -82118.791 | AA20: =1.2*'Organized Input Output'!$L$11 * (EXP(V20/'Organized Input Output'!$N$11) - 1 - 1.72 * (V20/'Organized Input Output'!$N$11)^4 )^ 'Organized Input Output'!$M$11 -> 0.17836079
D21: =D20+0.2 -> 0.6 | E21: =(D21 * $B$11) * 60000 -> 11.309734 | F21: =$B$5*$B$6*$B$4 -> 255060 | G21: =($B$12*($B$3/($B$10))*(($B$5*D21^2)/2))+($B$13*($B$5*D21^2)/2) -> 20489.904 | H21: =E21 / 1000 / 60 -> 0.00018849556 | I21: =F21-G21 -> 234570.1 | U21: =U20+0.2 -> 0.6 | V21: =(U21 * $B$11) * 60000 -> 11.309734 | W21: =$B$5*$B$6*$B$4 + ($B$12*($B$3/$B$10)*($B$5*U21*U21/2)) + ($B$13*($B$5*U21*U21/2)) + $B$14*U21 -> 283795.7 | X21: =($B$7*(V21*V21) + $B$8*V21 + $B$9)*1000 -> 348630.11 | Y21: =V21 / 1000 / 60 -> 0.00018849556 | Z21: =W21-X21 -> -64834.405 | AA21: =1.2*'Organized Input Output'!$L$11 * (EXP(V21/'Organized Input Output'!$N$11) - 1 - 1.72 * (V21/'Organized Input Output'!$N$11)^4 )^ 'Organized Input Output'!$M$11 -> 0.22455832
D22: =D21+0.2 -> 0.8 | E22: =(D22 * $B$11) * 60000 -> 15.079645 | F22: =$B$5*$B$6*$B$4 -> 255060 | G22: =($B$12*($B$3/($B$10))*(($B$5*D22^2)/2))+($B$13*($B$5*D22^2)/2) -> 36426.495 | H22: =E22 / 1000 / 60 -> 0.00025132741 | I22: =F22-G22 -> 218633.5 | U22: =U21+0.2 -> 0.8 | V22: =(U22 * $B$11) * 60000 -> 15.079645 | W22: =$B$5*$B$6*$B$4 + ($B$12*($B$3/$B$10)*($B$5*U22*U22/2)) + ($B$13*($B$5*U22*U22/2)) + $B$14*U22 -> 302480.9 | X22: =($B$7*(V22*V22) + $B$8*V22 + $B$9)*1000 -> 345048.39 | Y22: =V22 / 1000 / 60 -> 0.00025132741 | Z22: =W22-X22 -> -42567.498 | AA22: =1.2*'Organized Input Output'!$L$11 * (EXP(V22/'Organized Input Output'!$N$11) - 1 - 1.72 * (V22/'Organized Input Output'!$N$11)^4 )^ 'Organized Input Output'!$M$11 -> 0.26490908
D23: =D22+0.2 -> 1 | E23: =(D23 * $B$11) * 60000 -> 18.849556 | F23: =$B$5*$B$6*$B$4 -> 255060 | G23: =($B$12*($B$3/($B$10))*(($B$5*D23^2)/2))+($B$13*($B$5*D23^2)/2) -> 56916.399 | H23: =E23 / 1000 / 60 -> 0.00031415927 | I23: =F23-G23 -> 198143.6 | U23: =U22+0.2 -> 1 | V23: =(U23 * $B$11) * 60000 -> 18.849556 | W23: =$B$5*$B$6*$B$4 + ($B$12*($B$3/$B$10)*($B$5*U23*U23/2)) + ($B$13*($B$5*U23*U23/2)) + $B$14*U23 -> 325719.4 | X23: =($B$7*(V23*V23) + $B$8*V23 + $B$9)*1000 -> 341037.47 | Y23: =V23 / 1000 / 60 -> 0.00031415927 | Z23: =W23-X23 -> -15318.069 | AA23: =1.2*'Organized Input Output'!$L$11 * (EXP(V23/'Organized Input Output'!$N$11) - 1 - 1.72 * (V23/'Organized Input Output'!$N$11)^4 )^ 'Organized Input Output'!$M$11 -> 0.30149324
D24: =D23+0.2 -> 1.2 | E24: =(D24 * $B$11) * 60000 -> 22.619467 | F24: =$B$5*$B$6*$B$4 -> 255060 | G24: =($B$12*($B$3/($B$10))*(($B$5*D24^2)/2))+($B$13*($B$5*D24^2)/2) -> 81959.615 | H24: =E24 / 1000 / 60 -> 0.00037699112 | I24: =F24-G24 -> 173100.39 | U24: =U23+0.2 -> 1.2 | V24: =(U24 * $B$11) * 60000 -> 22.619467 | W24: =$B$5*$B$6*$B$4 + ($B$12*($B$3/$B$10)*($B$5*U24*U24/2)) + ($B$13*($B$5*U24*U24/2)) + $B$14*U24 -> 353511.21 | X24: =($B$7*(V24*V24) + $B$8*V24 + $B$9)*1000 -> 336597.33 | Y24: =V24 / 1000 / 60 -> 0.00037699112 | Z24: =W24-X24 -> 16913.881 | AA24: =1.2*'Organized Input Output'!$L$11 * (EXP(V24/'Organized Input Output'!$N$11) - 1 - 1.72 * (V24/'Organized Input Output'!$N$11)^4 )^ 'Organized Input Output'!$M$11 -> 0.33534759
D25: =D24+0.2 -> 1.4 | E25: =(D25 * $B$11) * 60000 -> 26.389378 | F25: =$B$5*$B$6*$B$4 -> 255060 | G25: =($B$12*($B$3/($B$10))*(($B$5*D25^2)/2))+($B$13*($B$5*D25^2)/2) -> 111556.14 | H25: =E25 / 1000 / 60 -> 0.00043982297 | I25: =F25-G25 -> 143503.86 | U25: =U24+0.2 -> 1.4 | V25: =(U25 * $B$11) * 60000 -> 26.389378 | W25: =$B$5*$B$6*$B$4 + ($B$12*($B$3/$B$10)*($B$5*U25*U25/2)) + ($B$13*($B$5*U25*U25/2)) + $B$14*U25 -> 385856.34 | X25: =($B$7*(V25*V25) + $B$8*V25 + $B$9)*1000 -> 331727.99 | Y25: =V25 / 1000 / 60 -> 0.00043982297 | Z25: =W25-X25 -> 54128.353 | AA25: =1.2*'Organized Input Output'!$L$11 * (EXP(V25/'Organized Input Output'!$N$11) - 1 - 1.72 * (V25/'Organized Input Output'!$N$11)^4 )^ 'Organized Input Output'!$M$11 -> 0.36705564
D26: =D25+0.2 -> 1.6 | E26: =(D26 * $B$11) * 60000 -> 30.159289 | F26: =$B$5*$B$6*$B$4 -> 255060 | G26: =($B$12*($B$3/($B$10))*(($B$5*D26^2)/2))+($B$13*($B$5*D26^2)/2) -> 145705.98 | H26: =E26 / 1000 / 60 -> 0.00050265482 | I26: =F26-G26 -> 109354.02 | U26: =U25+0.2 -> 1.6 | V26: =(U26 * $B$11) * 60000 -> 30.159289 | W26: =$B$5*$B$6*$B$4 + ($B$12*($B$3/$B$10)*($B$5*U26*U26/2)) + ($B$13*($B$5*U26*U26/2)) + $B$14*U26 -> 422754.78 | X26: =($B$7*(V26*V26) + $B$8*V26 + $B$9)*1000 -> 326429.44 | Y26: =V26 / 1000 / 60 -> 0.00050265482 | Z26: =W26-X26 -> 96325.345 | AA26: =1.2*'Organized Input Output'!$L$11 * (EXP(V26/'Organized Input Output'!$N$11) - 1 - 1.72 * (V26/'Organized Input Output'!$N$11)^4 )^ 'Organized Input Output'!$M$11 -> 0.39696567
D27: =D26+0.2 -> 1.8 | E27: =(D27 * $B$11) * 60000 -> 33.929201 | F27: =$B$5*$B$6*$B$4 -> 255060 | G27: =($B$12*($B$3/($B$10))*(($B$5*D27^2)/2))+($B$13*($B$5*D27^2)/2) -> 184409.13 | H27: =E27 / 1000 / 60 -> 0.00056548668 | I27: =F27-G27 -> 70650.867 | U27: =U26+0.2 -> 1.8 | V27: =(U27 * $B$11) * 60000 -> 33.929201 | W27: =$B$5*$B$6*$B$4 + ($B$12*($B$3/$B$10)*($B$5*U27*U27/2)) + ($B$13*($B$5*U27*U27/2)) + $B$14*U27 -> 464206.53 | X27: =($B$7*(V27*V27) + $B$8*V27 + $B$9)*1000 -> 320701.67 | Y27: =V27 / 1000 / 60 -> 0.00056548668 | Z27: =W27-X27 -> 143504.86 | AA27: =1.2*'Organized Input Output'!$L$11 * (EXP(V27/'Organized Input Output'!$N$11) - 1 - 1.72 * (V27/'Organized Input Output'!$N$11)^4 )^ 'Organized Input Output'!$M$11 -> 0.42528866
D28: =D27+0.2 -> 2 | E28: =(D28 * $B$11) * 60000 -> 37.699112 | F28: =$B$5*$B$6*$B$4 -> 255060 | G28: =($B$12*($B$3/($B$10))*(($B$5*D28^2)/2))+($B$13*($B$5*D28^2)/2) -> 227665.6 | H28: =E28 / 1000 / 60 -> 0.00062831853 | I28: =F28-G28 -> 27394.403 | U28: =U27+0.2 -> 2 | V28: =(U28 * $B$11) * 60000 -> 37.699112 | W28: =$B$5*$B$6*$B$4 + ($B$12*($B$3/$B$10)*($B$5*U28*U28/2)) + ($B$13*($B$5*U28*U28/2)) + $B$14*U28 -> 510211.6 | X28: =($B$7*(V28*V28) + $B$8*V28 + $B$9)*1000 -> 314544.7 | Y28: =V28 / 1000 / 60 -> 0.00062831853 | Z28: =W28-X28 -> 195666.89 | AA28: =1.2*'Organized Input Output'!$L$11 * (EXP(V28/'Organized Input Output'!$N$11) - 1 - 1.72 * (V28/'Organized Input Output'!$N$11)^4 )^ 'Organized Input Output'!$M$11 -> 0.45214832 | AD28: Flow Rate | AE28: {=MIN(ABS(Z18:Z33))} -> 15318.069
D29: =D28+0.2 -> 2.2 | E29: =(D29 * $B$11) * 60000 -> 41.469023 | F29: =$B$5*$B$6*$B$4 -> 255060 | G29: =($B$12*($B$3/($B$10))*(($B$5*D29^2)/2))+($B$13*($B$5*D29^2)/2) -> 275475.37 | H29: =E29 / 1000 / 60 -> 0.00069115038 | I29: =F29-G29 -> -20415.372 | U29: =U28+0.2 -> 2.2 | V29: =(U29 * $B$11) * 60000 -> 41.469023 | W29: =$B$5*$B$6*$B$4 + ($B$12*($B$3/$B$10)*($B$5*U29*U29/2)) + ($B$13*($B$5*U29*U29/2)) + $B$14*U29 -> 560769.97 | X29: =($B$7*(V29*V29) + $B$8*V29 + $B$9)*1000 -> 307958.52 | Y29: =V29 / 1000 / 60 -> 0.00069115038 | Z29: =W29-X29 -> 252811.45 | AA29: =1.2*'Organized Input Output'!$L$11 * (EXP(V29/'Organized Input Output'!$N$11) - 1 - 1.72 * (V29/'Organized Input Output'!$N$11)^4 )^ 'Organized Input Output'!$M$11 -> 0.47760896 | AD29: Q [LPM] | AE29: {=INDEX(V18:V33, MATCH(MIN(ABS(Z18:Z33)), ABS(Z18:Z33), 0))} -> 18.849556
D30: =D29+0.2 -> 2.4 | E30: =(D30 * $B$11) * 60000 -> 45.238934 | F30: =$B$5*$B$6*$B$4 -> 255060 | G30: =($B$12*($B$3/($B$10))*(($B$5*D30^2)/2))+($B$13*($B$5*D30^2)/2) -> 327838.46 | H30: =E30 / 1000 / 60 -> 0.00075398224 | I30: =F30-G30 -> -72778.459 | K30: Flow Rate | L30: {=MIN(ABS(I18:I33))} -> 20415.372 | U30: =U29+0.2 -> 2.4 | V30: =(U30 * $B$11) * 60000 -> 45.238934 | W30: =$B$5*$B$6*$B$4 + ($B$12*($B$3/$B$10)*($B$5*U30*U30/2)) + ($B$13*($B$5*U30*U30/2)) + $B$14*U30 -> 615881.66 | X30: =($B$7*(V30*V30) + $B$8*V30 + $B$9)*1000 -> 300943.13 | Y30: =V30 / 1000 / 60 -> 0.00075398224 | Z30: =W30-X30 -> 314938.53 | AA30: =1.2*'Organized Input Output'!$L$11 * (EXP(V30/'Organized Input Output'!$N$11) - 1 - 1.72 * (V30/'Organized Input Output'!$N$11)^4 )^ 'Organized Input Output'!$M$11 -> 0.50169195 | AD30: Q [m^3/day] | AE30: =AE29*1.44 -> 27.143361
D31: =D30+0.2 -> 2.6 | E31: =(D31 * $B$11) * 60000 -> 49.008845 | F31: =$B$5*$B$6*$B$4 -> 255060 | G31: =($B$12*($B$3/($B$10))*(($B$5*D31^2)/2))+($B$13*($B$5*D31^2)/2) -> 384754.86 | H31: =E31 / 1000 / 60 -> 0.00081681409 | I31: =F31-G31 -> -129694.86 | K31: Q [LPM] | L31: {=INDEX(E18:E33, MATCH(MIN(ABS(I18:I33)), ABS(I18:I33), 0))} -> 41.469023 | U31: =U30+0.2 -> 2.6 | V31: =(U31 * $B$11) * 60000 -> 49.008845 | W31: =$B$5*$B$6*$B$4 + ($B$12*($B$3/$B$10)*($B$5*U31*U31/2)) + ($B$13*($B$5*U31*U31/2)) + $B$14*U31 -> 675546.66 | X31: =($B$7*(V31*V31) + $B$8*V31 + $B$9)*1000 -> 293498.53 | Y31: =V31 / 1000 / 60 -> 0.00081681409 | Z31: =W31-X31 -> 382048.13 | AA31: =1.2*'Organized Input Output'!$L$11 * (EXP(V31/'Organized Input Output'!$N$11) - 1 - 1.72 * (V31/'Organized Input Output'!$N$11)^4 )^ 'Organized Input Output'!$M$11 -> 0.52438604 | AD31: Efficiency | AE31: =INDEX(AA18:AA33, MATCH(AE29, V18:V33, 0)) -> 0.30149324
D32: =D31+0.2 -> 2.8 | E32: =(D32 * $B$11) * 60000 -> 52.778757 | F32: =$B$5*$B$6*$B$4 -> 255060 | G32: =($B$12*($B$3/($B$10))*(($B$5*D32^2)/2))+($B$13*($B$5*D32^2)/2) -> 446224.57 | H32: =E32 / 1000 / 60 -> 0.00087964594 | I32: =F32-G32 -> -191164.57 | K32: Q [m^3/day] | L32: =L31*1.44 -> 59.715393 | U32: =U31+0.2 -> 2.8 | V32: =(U32 * $B$11) * 60000 -> 52.778757 | W32: =$B$5*$B$6*$B$4 + ($B$12*($B$3/$B$10)*($B$5*U32*U32/2)) + ($B$13*($B$5*U32*U32/2)) + $B$14*U32 -> 739764.97 | X32: =($B$7*(V32*V32) + $B$8*V32 + $B$9)*1000 -> 285624.72 | Y32: =V32 / 1000 / 60 -> 0.00087964594 | Z32: =W32-X32 -> 454140.25 | AA32: =1.2*'Organized Input Output'!$L$11 * (EXP(V32/'Organized Input Output'!$N$11) - 1 - 1.72 * (V32/'Organized Input Output'!$N$11)^4 )^ 'Organized Input Output'!$M$11 -> 0.54565374
D33: =D32+0.2 -> 3 | E33: =(D33 * $B$11) * 60000 -> 56.548668 | F33: =$B$5*$B$6*$B$4 -> 255060 | G33: =($B$12*($B$3/($B$10))*(($B$5*D33^2)/2))+($B$13*($B$5*D33^2)/2) -> 512247.59 | H33: =E33 / 1000 / 60 -> 0.0009424778 | I33: =F33-G33 -> -257187.59 | U33: =U32+0.2 -> 3 | V33: =(U33 * $B$11) * 60000 -> 56.548668 | W33: =$B$5*$B$6*$B$4 + ($B$12*($B$3/$B$10)*($B$5*U33*U33/2)) + ($B$13*($B$5*U33*U33/2)) + $B$14*U33 -> 808536.59 | X33: =($B$7*(V33*V33) + $B$8*V33 + $B$9)*1000 -> 277321.7 | Y33: =V33 / 1000 / 60 -> 0.0009424778 | Z33: =W33-X33 -> 531214.89 | AA33: =1.2*'Organized Input Output'!$L$11 * (EXP(V33/'Organized Input Output'!$N$11) - 1 - 1.72 * (V33/'Organized Input Output'!$N$11)^4 )^ 'Organized Input Output'!$M$11 -> 0.5654355
B34: goal seek | D34: 1.9809089 | E34: =(D34 * $B$11) * 60000 -> 37.339253 | F34: =$B$5*$B$6*$B$4 -> 255060 | G34: =($B$12*($B$3/($B$10))*(($B$5*D34^2)/2))+($B$13*($B$5*D34^2)/2) -> 223339.95 | H34: =E34 / 1000 / 60 -> 0.00062232088 | I34: =F34-G34 -> 31720.05 | U34: 2.5458162 | V34: =(U34 * $B$11) * 60000 -> 47.987505 | W34: =$B$5*$B$6*$B$4 + ($B$12*($B$3/$B$10)*($B$5*U34*U34/2)) + ($B$13*($B$5*U34*U34/2)) + $B$14*U34 -> 658932.58 | X34: =($B$7*(V34*V34) + $B$8*V34 + $B$9)*1000 -> 295557.8 | Y34: =V34 / 1000 / 60 -> 0.00079979175 | Z34: =W34-X34 -> 363374.78
E35: on demand flow rate | V35: =V34*1.44 -> 69.102007

Sheet Solar Energy Model
A1: Solar Energy Model
A3: Sunshine Data | D3: HES-260(Solar)
A4: Month | B4: Sunshine/day | D4: Solar Intensity | E4: 275 | F4: W/m^2
A5: [-] | B5: [hr] | D5: Panel area | E5: ='Organized Input Output'!$AD$9 -> 8 | F5: m^2
A6: Jan | B6: 8.5 | D6: # of panels | E6: ='Organized Input Output'!$AC$9 -> 5
A7: Feb | B7: 10 | D7: Efficiency | E7: ='Organized Input Output'!$AB$9 -> 0.15
A8: Mar | B8: 11.8 | D8: Batteries
A9: Apr | B9: 13.6 | D9: Capacity | E9: ='Organized Input Output'!AC11*2000 -> 2000 | F9: Wh
A10: May | B10: 15.3 | D10: # of batteries | E10: ='Organized Input Output'!$AC$11 -> 1
A11: Jun | B11: 16 | D11: Efficiency | E11: 0.96
A12: Jul | B12: 15.75 | D12: Electrical Power Demand
A13: Aug | B13: 14.2 | D13: Use per day | E13: 15 | F13: hours
A14: Sep | B14: 12.5
A15: Oct | B15: 10.75
A16: Nov | B16: 9
A17: Dec | B17: 8.25
A19: Day | B19: Month | C19: Date | D19: Hours of Sunshine | E19: Incident Solar Energy | F19: Energy Generated | G19: Energy In | H19: Energy Needed | I19: Energy Out | J19: Energy Stored | K19: Meets requirement? | M19: Days Power Requirement not met | O19: =IF(MAX(G22-I22,0)>$E$9,$E$9,MAX(G22-I22,0)) -> 552.22619
A20: [-] | B20: [-] | C20: [-] | D20: [hr] | E20: [Whr] | F20: [Whr] | G20: [Whr] | H20: [Whr] | I20: [Whr] | J20: [Wh] | K20: [-] | M20: =SUM(K21:K386) -> 0
A21: 1 | B21: Jan | C21: 1 | D21: =$B$6 -> 8.5 | E21: =$E$4 * ($E$5)*D21 -> 18700 | F21: =E21*$E$7 -> 2805 | G21: =F21*$E$11 -> 2692.8 | H21: ='Ozone-Energy'!P11*10^6/86400 * 24 -> 1030.7175 | I21: =IF( G21-H21*(1/$E$11) < 0, G21/$E$11, H21/$E$11) -> 1073.664 | J21: =E9 -> 2000 | K21: =IF(J21<=0, 1, 0) -> 0
A22: 2 | B22: Jan | C22: 2 | D22: =$B$6 -> 8.5 | E22: =$E$4 * ($E$6)*D22 -> 11687.5 | F22: =E22*$E$7 -> 1753.125 | G22: =F22*$E$11 -> 1683 | H22: ='Ozone-Energy'!P12*10^6/86400 * 24 -> 1085.5429 | I22: =IF( J21+G22-H22*(1/$E$11) < 0, 0, H22*(1/$E$11)) -> 1130.7738 | J22: =MAX(MIN(J21 + G21 - I21, $E$9), 0) -> 2000 | K22: =IF(J22<=0, 1, 0) -> 0
A23: 3 | B23: Jan | C23: 3 | D23: =$B$6 -> 8.5 | E23: =$E$4 * ($E$6)*D23 -> 11687.5 | F23: =E23*$E$7 -> 1753.125 | G23: =F23*$E$11 -> 1683 | H23: ='Ozone-Energy'!P13*10^6/86400 * 24 -> 0 | I23: =IF( J22+G23-H23*(1/$E$11) < 0, 0, H23*(1/$E$11)) -> 0 | J23: =MAX(MIN(J22 + G22 - I22, $E$9), 0) -> 2000 | K23: =IF(J23<=0, 1, 0) -> 0
A24: 4 | B24: Jan | C24: 4 | D24: =$B$6 -> 8.5 | E24: =$E$4 * ($E$6)*D24 -> 11687.5 | F24: =E24*$E$7 -> 1753.125 | G24: =F24*$E$11 -> 1683 | H24: ='Ozone-Energy'!P14*10^6/86400 * 24 -> 0 | I24: =IF( J23+G24-H24*(1/$E$11) < 0, 0, H24*(1/$E$11)) -> 0 | J24: =MAX(MIN(J23 + G23 - I23, $E$9), 0) -> 2000 | K24: =IF(J24<=0, 1, 0) -> 0
A25: 5 | B25: Jan | C25: 5 | D25: =$B$6 -> 8.5 | E25: =$E$4 * ($E$6)*D25 -> 11687.5 | F25: =E25*$E$7 -> 1753.125 | G25: =F25*$E$11 -> 1683 | H25: ='Ozone-Energy'!P15*10^6/86400 * 24 -> 0 | I25: =IF( J24+G25-H25*(1/$E$11) < 0, 0, H25*(1/$E$11)) -> 0 | J25: =MAX(MIN(J24 + G24 - I24, $E$9), 0) -> 2000 | K25: =IF(J25<=0, 1, 0) -> 0
A26: 6 | B26: Jan | C26: 6 | D26: =$B$6 -> 8.5 | E26: =$E$4 * ($E$6)*D26 -> 11687.5 | F26: =E26*$E$7 -> 1753.125 | G26: =F26*$E$11 -> 1683 | H26: ='Ozone-Energy'!P16*10^6/86400 * 24 -> 274.12698 | I26: =IF( J25+G26-H26*(1/$E$11) < 0, 0, H26*(1/$E$11)) -> 285.54894 | J26: =MAX(MIN(J25 + G25 - I25, $E$9), 0) -> 2000 | K26: =IF(J26<=0, 1, 0) -> 0
A27: 7 | B27: Jan | C27: 7 | D27: =$B$6 -> 8.5 | E27: =$E$4 * ($E$6)*D27 -> 11687.5 | F27: =E27*$E$7 -> 1753.125 | G27: =F27*$E$11 -> 1683 | H27: ='Ozone-Energy'!P17*10^6/86400 * 24 -> 1118.4381 | I27: =IF( J26+G27-H27*(1/$E$11) < 0, 0, H27*(1/$E$11)) -> 1165.0397 | J27: =MAX(MIN(J26 + G26 - I26, $E$9), 0) -> 2000 | K27: =IF(J27<=0, 1, 0) -> 0
A28: 8 | B28: Jan | C28: 8 | D28: =$B$6 -> 8.5 | E28: =$E$4 * ($E$6)*D28 -> 11687.5 | F28: =E28*$E$7 -> 1753.125 | G28: =F28*$E$11 -> 1683 | H28: ='Ozone-Energy'!P18*10^6/86400 * 24 -> 1359.6698 | I28: =IF( J27+G28-H28*(1/$E$11) < 0, 0, H28*(1/$E$11)) -> 1416.3228 | J28: =MAX(MIN(J27 + G27 - I27, $E$9), 0) -> 2000 | K28: =IF(J28<=0, 1, 0) -> 0
A29: 9 | B29: Jan | C29: 9 | D29: =$B$6 -> 8.5 | E29: =$E$4 * ($E$6)*D29 -> 11687.5 | F29: =E29*$E$7 -> 1753.125 | G29: =F29*$E$11 -> 1683 | H29: ='Ozone-Energy'!P19*10^6/86400 * 24 -> 1864.0635 | I29: =IF( J28+G29-H29*(1/$E$11) < 0, 0, H29*(1/$E$11)) -> 1941.7328 | J29: =MAX(MIN(J28 + G28 - I28, $E$9), 0) -> 2000 | K29: =IF(J29<=0, 1, 0) -> 0
A30: 10 | B30: Jan | C30: 10 | D30: =$B$6 -> 8.5 | E30: =$E$4 * ($E$6)*D30 -> 11687.5 | F30: =E30*$E$7 -> 1753.125 | G30: =F30*$E$11 -> 1683 | H30: ='Ozone-Energy'!P20*10^6/86400 * 24 -> 2445.2127 | I30: =IF( J29+G30-H30*(1/$E$11) < 0, 0, H30*(1/$E$11)) -> 2547.0966 | J30: =MAX(MIN(J29 + G29 - I29, $E$9), 0) -> 1741.2672 | K30: =IF(J30<=0, 1, 0) -> 0
A31: 11 | B31: Jan | C31: 11 | D31: =$B$6 -> 8.5 | E31: =$E$4 * ($E$6)*D31 -> 11687.5 | F31: =E31*$E$7 -> 1753.125 | G31: =F31*$E$11 -> 1683 | H31: ='Ozone-Energy'!P21*10^6/86400 * 24 -> 789.48571 | I31: =IF( J30+G31-H31*(1/$E$11) < 0, 0, H31*(1/$E$11)) -> 822.38095 | J31: =MAX(MIN(J30 + G30 - I30, $E$9), 0) -> 877.17063 | K31: =IF(J31<=0, 1, 0) -> 0
A32: 12 | B32: Jan | C32: 12 | D32: =$B$6 -> 8.5 | E32: =$E$4 * ($E$6)*D32 -> 11687.5 | F32: =E32*$E$7 -> 1753.125 | G32: =F32*$E$11 -> 1683 | H32: ='Ozone-Energy'!P22*10^6/86400 * 24 -> 2752.2349 | I32: =IF( J31+G32-H32*(1/$E$11) < 0, 0, H32*(1/$E$11)) -> 0 | J32: =MAX(MIN(J31 + G31 - I31, $E$9), 0) -> 1737.7897 | K32: =IF(J32<=0, 1, 0) -> 0
A33: 13 | B33: Jan | C33: 13 | D33: =$B$6 -> 8.5 | E33: =$E$4 * ($E$6)*D33 -> 11687.5 | F33: =E33*$E$7 -> 1753.125 | G33: =F33*$E$11 -> 1683 | H33: ='Ozone-Energy'!P23*10^6/86400 * 24 -> 526.32381 | I33: =IF( J32+G33-H33*(1/$E$11) < 0, 0, H33*(1/$E$11)) -> 548.25397 | J33: =MAX(MIN(J32 + G32 - I32, $E$9), 0) -> 2000 | K33: =IF(J33<=0, 1, 0) -> 0
... A51: 31 | B51: Jan | C51: 31 | D51: =$B$6 -> 8.5 | E51: =$E$4 * ($E$6)*D51 -> 11687.5 | F51: =E51*$E$7 -> 1753.125 | G51: =F51*$E$11 -> 1683 | H51: ='Ozone-Energy'!P41*10^6/86400 * 24 -> 1342.546 | I51: =IF( J50+G51-H51*(1/$E$11) < 0, 0, H51*(1/$E$11)) -> 1398.4854 | J51: =MAX(MIN(J50 + G50 - I50, $E$9), 0) -> 2000 | K51: =IF(J51<=0, 1, 0) -> 0
A52: 32 | B52: Feb | C52: 1 | D52: 10 | E52: =$E$4 * ($E$6)*D52 -> 13750 | F52: =E52*$E$7 -> 2062.5 | G52: =F52*$E$11 -> 1980 | H52: ='Ozone-Energy'!P42*10^6/86400 * 24 -> 9286.9905 | I52: =IF( J51+G52-H52*(1/$E$11) < 0, 0, H52*(1/$E$11)) -> 0 | J52: =MAX(MIN(J51 + G51 - I51, $E$9), 0) -> 2000 | K52: =IF(J52<=0, 1, 0) -> 0
A53: 33 | B53: Feb | C53: 2 | D53: 10 | E53: =$E$4 * ($E$6)*D53 -> 13750 | F53: =E53*$E$7 -> 2062.5 | G53: =F53*$E$11 -> 1980 | H53: ='Ozone-Energy'!P43*10^6/86400 * 24 -> 1200 | I53: =IF( J52+G53-H53*(1/$E$11) < 0, 0, H53*(1/$E$11)) -> 1250 | J53: =MAX(MIN(J52 + G52 - I52, $E$9), 0) -> 2000 | K53: =IF(J53<=0, 1, 0) -> 0
A54: 34 | B54: Feb | C54: 3 | D54: 10 | E54: =$E$4 * ($E$6)*D54 -> 13750 | F54: =E54*$E$7 -> 2062.5 | G54: =F54*$E$11 -> 1980 | H54: ='Ozone-Energy'!P44*10^6/86400 * 24 -> 1200 | I54: =IF( J53+G54-H54*(1/$E$11) < 0, 0, H54*(1/$E$11)) -> 1250 | J54: =MAX(MIN(J53 + G53 - I53, $E$9), 0) -> 2000 | K54: =IF(J54<=0, 1, 0) -> 0
A55: 35 | B55: Feb | C55: 4 | D55: 10 | E55: =$E$4 * ($E$6)*D55 -> 13750 | F55: =E55*$E$7 -> 2062.5 | G55: =F55*$E$11 -> 1980 | H55: ='Ozone-Energy'!P45*10^6/86400 * 24 -> 1200 | I55: =IF( J54+G55-H55*(1/$E$11) < 0, 0, H55*(1/$E$11)) -> 1250 | J55: =MAX(MIN(J54 + G54 - I54, $E$9), 0) -> 2000 | K55: =IF(J55<=0, 1, 0) -> 0
A56: 36 | B56: Feb | C56: 5 | D56: 10 | E56: =$E$4 * ($E$6)*D56 -> 13750 | F56: =E56*$E$7 -> 2062.5 | G56: =F56*$E$11 -> 1980 | H56: ='Ozone-Energy'!P46*10^6/86400 * 24 -> 1200 | I56: =IF( J55+G56-H56*(1/$E$11) < 0, 0, H56*(1/$E$11)) -> 1250 | J56: =MAX(MIN(J55 + G55 - I55, $E$9), 0) -> 2000 | K56: =IF(J56<=0, 1, 0) -> 0
A57: 37 | B57: Feb | C57: 6 | D57: 10 | E57: =$E$4 * ($E$6)*D57 -> 13750 | F57: =E57*$E$7 -> 2062.5 | G57: =F57*$E$11 -> 1980 | H57: ='Ozone-Energy'!P47*10^6/86400 * 24 -> 1200 | I57: =IF( J56+G57-H57*(1/$E$11) < 0, 0, H57*(1/$E$11)) -> 1250 | J57: =MAX(MIN(J56 + G56 - I56, $E$9), 0) -> 2000 | K57: =IF(J57<=0, 1, 0) -> 0
A58: 38 | B58: Feb | C58: 7 | D58: 10 | E58: =$E$4 * ($E$6)*D58 -> 13750 | F58: =E58*$E$7 -> 2062.5 | G58: =F58*$E$11 -> 1980 | H58: ='Ozone-Energy'!P48*10^6/86400 * 24 -> 1200 | I58: =IF( J57+G58-H58*(1/$E$11) < 0, 0, H58*(1/$E$11)) -> 1250 | J58: =MAX(MIN(J57 + G57 - I57, $E$9), 0) -> 2000 | K58: =IF(J58<=0, 1, 0) -> 0
A59: 39 | B59: Feb | C59: 8 | D59: 10 | E59: =$E$4 * ($E$6)*D59 -> 13750 | F59: =E59*$E$7 -> 2062.5 | G59: =F59*$E$11 -> 1980 | H59: ='Ozone-Energy'!P49*10^6/86400 * 24 -> 1200 | I59: =IF( J58+G59-H59*(1/$E$11) < 0, 0, H59*(1/$E$11)) -> 1250 | J59: =MAX(MIN(J58 + G58 - I58, $E$9), 0) -> 2000 | K59: =IF(J59<=0, 1, 0) -> 0
...

Sheet Maintainance
A1: Loss coefficient | B1: k
A2: Pressure from storage
A3: Consumption | B3: ='Organized Input Output'!D14 -> 745
B6: Filter Settings | C6: Filter size | D6: Present? | E6: Cf Pa/(m/s) | F6: Actual filter life (L) | G6: Filter Life Data (L) | J6: Filter location (B or A) | M6: Total Filter Mantinence Days
G7: No pre filter | H7: 5 um pre | I7: 200 um pre | M7: =SUM(I17:I390) -> 14
C8: 1 um filter | D8: ='Organized Input Output'!R7 -> y | E8: ='Organized Input Output'!S7 -> 2295.081 | F8: ='Organized Input Output'!T7 -> 20000 | G8: ='Organized Input Output'!U7 -> 5000 | H8: ='Organized Input Output'!V7 -> 20000 | I8: ='Organized Input Output'!W7 -> 15000
C9: 5 um filter | D9: ='Organized Input Output'!R8 -> y | E9: ='Organized Input Output'!S8 -> 1144.7919 | F9: ='Organized Input Output'!T8 -> 20000 | G9: ='Organized Input Output'!U8 -> 10000 | I9: ='Organized Input Output'!W8 -> 20000
C10: 200 um filter | D10: ='Organized Input Output'!R9 -> y | E10: ='Organized Input Output'!S9 -> 57.30831 | F10: ='Organized Input Output'!T9 -> 20000 | G10: ='Organized Input Output'!U9 -> 20000
C11: Total | E11: ='Organized Input Output'!S10 -> 3497.1812
G15: Maintainance | P15: Maintenance required for 4000 Watt Diesel Generator
B16: day | C16: 1um filter | D16: 5um filter | E16: 200um filter | F16: 1um | G16: 5um filter | H16: 200um filter | I16: days of operation
B17: 1 | C17: =B3 -> 745 | D17: =IF(D9 = "y", C17, 0) -> 745 | E17: =IF(D10 = "y", C17, 0) -> 745 | I17: =IF(SUM(F17:H17)>0,1,"") | J17: =IF(SUM(G17:I17)>0,J17+1,"") | P17: Oil change and maintenance operation required every 250 hours
B18: 2 | C18: =IF(C17+$B$3>$F$8,$B$3,C17+$B$3) -> 1490 | D18: =IF($D$17 = 0, 0, IF(D17+$B$3>$F$9,$B$3,D17+$B$3)) -> 1490 | E18: =IF($E$17 = 0, 0, IF(E17+$B$3>$F$10,$B$3,E17+$B$3)) -> 1490 | F18: =IF((C18=$B$3),1,0) -> 0 | G18: =IF((D18=$B$3),1,0) -> 0 | H18: =IF((E18=$B$3),1,0) -> 0 | I18: =IF(SUM(F18:H18)>0,1,"") | P18: Refuelling (maintenance operation) every 100 L of diesel consumed
B19: 3 | C19: =IF(C18+$B$3>$F$8,$B$3,C18+$B$3) -> 2235 | D19: =IF($D$17 = 0, 0, IF(D18+$B$3>$F$9,$B$3,D18+$B$3)) -> 2235 | E19: =IF($E$17 = 0, 0, IF(E18+$B$3>$F$10,$B$3,E18+$B$3)) -> 2235 | F19: =IF((C19=$B$3),1,0) -> 0 | G19: =IF((D19=$B$3),1,0) -> 0 | H19: =IF((E19=$B$3),1,0) -> 0 | I19: =IF(SUM(F19:H19)>0,1,"")
B20: 4 | C20: =IF(C19+$B$3>$F$8,$B$3,C19+$B$3) -> 2980 | D20: =IF($D$17 = 0, 0, IF(D19+$B$3>$F$9,$B$3,D19+$B$3)) -> 2980 | E20: =IF($E$17 = 0, 0, IF(E19+$B$3>$F$10,$B$3,E19+$B$3)) -> 2980 | F20: =IF((C20=$B$3),1,0) -> 0 | G20: =IF((D20=$B$3),1,0) -> 0 | H20: =IF((E20=$B$3),1,0) -> 0 | I20: =IF(SUM(F20:H20)>0,1,"")
B21: 5 | C21: =IF(C20+$B$3>$F$8,$B$3,C20+$B$3) -> 3725 | D21: =IF($D$17 = 0, 0, IF(D20+$B$3>$F$9,$B$3,D20+$B$3)) -> 3725 | E21: =IF($E$17 = 0, 0, IF(E20+$B$3>$F$10,$B$3,E20+$B$3)) -> 3725 | F21: =IF((C21=$B$3),1,0) -> 0 | G21: =IF((D21=$B$3),1,0) -> 0 | H21: =IF((E21=$B$3),1,0) -> 0 | I21: =IF(SUM(F21:H21)>0,1,"")
B22: 6 | C22: =IF(C21+$B$3>$F$8,$B$3,C21+$B$3) -> 4470 | D22: =IF($D$17 = 0, 0, IF(D21+$B$3>$F$9,$B$3,D21+$B$3)) -> 4470 | E22: =IF($E$17 = 0, 0, IF(E21+$B$3>$F$10,$B$3,E21+$B$3)) -> 4470 | F22: =IF((C22=$B$3),1,0) -> 0 | G22: =IF((D22=$B$3),1,0) -> 0 | H22: =IF((E22=$B$3),1,0) -> 0 | I22: =IF(SUM(F22:H22)>0,1,"")
B23: 7 | C23: =IF(C22+$B$3>$F$8,$B$3,C22+$B$3) -> 5215 | D23: =IF($D$17 = 0, 0, IF(D22+$B$3>$F$9,$B$3,D22+$B$3)) -> 5215 | E23: =IF($E$17 = 0, 0, IF(E22+$B$3>$F$10,$B$3,E22+$B$3)) -> 5215 | F23: =IF((C23=$B$3),1,0) -> 0 | G23: =IF((D23=$B$3),1,0) -> 0 | H23: =IF((E23=$B$3),1,0) -> 0 | I23: =IF(SUM(F23:H23)>0,1,"")
B24: 8 | C24: =IF(C23+$B$3>$F$8,$B$3,C23+$B$3) -> 5960 | D24: =IF($D$17 = 0, 0, IF(D23+$B$3>$F$9,$B$3,D23+$B$3)) -> 5960 | E24: =IF($E$17 = 0, 0, IF(E23+$B$3>$F$10,$B$3,E23+$B$3)) -> 5960 | F24: =IF((C24=$B$3),1,0) -> 0 | G24: =IF((D24=$B$3),1,0) -> 0 | H24: =IF((E24=$B$3),1,0) -> 0 | I24: =IF(SUM(F24:H24)>0,1,"")
B25: 9 | C25: =IF(C24+$B$3>$F$8,$B$3,C24+$B$3) -> 6705 | D25: =IF($D$17 = 0, 0, IF(D24+$B$3>$F$9,$B$3,D24+$B$3)) -> 6705 | E25: =IF($E$17 = 0, 0, IF(E24+$B$3>$F$10,$B$3,E24+$B$3)) -> 6705 | F25: =IF((C25=$B$3),1,0) -> 0 | G25: =IF((D25=$B$3),1,0) -> 0 | H25: =IF((E25=$B$3),1,0) -> 0 | I25: =IF(SUM(F25:H25)>0,1,"")
B26: 10 | C26: =IF(C25+$B$3>$F$8,$B$3,C25+$B$3) -> 7450 | D26: =IF($D$17 = 0, 0, IF(D25+$B$3>$F$9,$B$3,D25+$B$3)) -> 7450 | E26: =IF($E$17 = 0, 0, IF(E25+$B$3>$F$10,$B$3,E25+$B$3)) -> 7450 | F26: =IF((C26=$B$3),1,0) -> 0 | G26: =IF((D26=$B$3),1,0) -> 0 | H26: =IF((E26=$B$3),1,0) -> 0 | I26: =IF(SUM(F26:H26)>0,1,"")
B27: 11 | C27: =IF(C26+$B$3>$F$8,$B$3,C26+$B$3) -> 8195 | D27: =IF($D$17 = 0, 0, IF(D26+$B$3>$F$9,$B$3,D26+$B$3)) -> 8195 | E27: =IF($E$17 = 0, 0, IF(E26+$B$3>$F$10,$B$3,E26+$B$3)) -> 8195 | F27: =IF((C27=$B$3),1,0) -> 0 | G27: =IF((D27=$B$3),1,0) -> 0 | H27: =IF((E27=$B$3),1,0) -> 0 | I27: =IF(SUM(F27:H27)>0,1,"")
B28: 12 | C28: =IF(C27+$B$3>$F$8,$B$3,C27+$B$3) -> 8940 | D28: =IF($D$17 = 0, 0, IF(D27+$B$3>$F$9,$B$3,D27+$B$3)) -> 8940 | E28: =IF($E$17 = 0, 0, IF(E27+$B$3>$F$10,$B$3,E27+$B$3)) -> 8940 | F28: =IF((C28=$B$3),1,0) -> 0 | G28: =IF((D28=$B$3),1,0) -> 0 | H28: =IF((E28=$B$3),1,0) -> 0 | I28: =IF(SUM(F28:H28)>0,1,"")
B29: 13 | C29: =IF(C28+$B$3>$F$8,$B$3,C28+$B$3) -> 9685 | D29: =IF($D$17 = 0, 0, IF(D28+$B$3>$F$9,$B$3,D28+$B$3)) -> 9685 | E29: =IF($E$17 = 0, 0, IF(E28+$B$3>$F$10,$B$3,E28+$B$3)) -> 9685 | F29: =IF((C29=$B$3),1,0) -> 0 | G29: =IF((D29=$B$3),1,0) -> 0 | H29: =IF((E29=$B$3),1,0) -> 0 | I29: =IF(SUM(F29:H29)>0,1,"")
B30: 14 | C30: =IF(C29+$B$3>$F$8,$B$3,C29+$B$3) -> 10430 | D30: =IF($D$17 = 0, 0, IF(D29+$B$3>$F$9,$B$3,D29+$B$3)) -> 10430 | E30: =IF($E$17 = 0, 0, IF(E29+$B$3>$F$10,$B$3,E29+$B$3)) -> 10430 | F30: =IF((C30=$B$3),1,0) -> 0 | G30: =IF((D30=$B$3),1,0) -> 0 | H30: =IF((E30=$B$3),1,0) -> 0 | I30: =IF(SUM(F30:H30)>0,1,"")
... B381: 365 | C381: =IF(C380+$B$3>$F$8,$B$3,C380+$B$3) -> 745 | D381: =IF($D$17 = 0, 0, IF(D380+$B$3>$F$9,$B$3,D380+$B$3)) -> 745 | E381: =IF($E$17 = 0, 0, IF(E380+$B$3>$F$10,$B$3,E380+$B$3)) -> 745 | F381: =IF((C381=$B$3),1,0) -> 1 | G381: =IF((D381=$B$3),1,0) -> 1 | H381: =IF((E381=$B$3),1,0) -> 1 | I381: =IF(SUM(F381:H381)>0,1,"") -> 1

Sheet Greenhouse Gases
A1: Greenhouse Gases Emission
B3: Parameters | C3: Daily Water Usage | D3: ='Organized Input Output'!D14 -> 745 | E3: L/day | G3: Constants | H3: Treatment for Water | I3: 0.1 | J3: kgCO2e/1000L
C4: Years | D4: 5 | E4: years | H4: Diesel emission | I4: 3.25 | J4: kgCO2e / L diesel
C5: Diesel Used | D5: ='Ozone-Energy'!Q5 -> 0 | E5: L | H5: Transport | I5: 6.4 | J5: kgCO2e/1000L
C6: Generator Manufacturing | D6: 1250 | E6: kgCO2e | H6: Storage & Distribution | I6: 2408 | J6: kgCO2e
C7: Battery Manufacturing | D7: 240 | E7: kgCO2e
B9: Total Water | C9: Existing GHG | D9: Diesel GHG | E9: Power System | F9: Proposed GHG | G9: Relative (in %)
B10: =D$3*365*D$4 -> 1359625 | C10: =B10*(0.1+6.4)/1000+2408 -> 11245.562 | D10: =($D$5*5)*$I$4 -> 0 | E10: =$D$6+$D$7+D10 -> 1490 | F10: =E10+$I$6 -> 3898 | G10: =F10/C10*100 -> 34.662561

Sheet Weather Data
A1: RWH Input-Output Data
A2: Team J-9
A3: Station 3 - 2013 | D3: Station 2 - 2015 | G3: Station 1 - 2015 | J3: Station 1 - 2014
A4: Date days starting on Jan 1 2013 | B4: Daily Rainfall (mm) | D4: Date days starting on Jan 1 2015 | E4: Daily Rainfall (mm) | G4: Date days starting on Jan 1 2015 | H4: Daily Rainfall (mm) | J4: Date days starting on Jan 1 2014 | K4: Daily Rainfall (mm)
A5: 1 | B5: 0 | D5: 1 | E5: 0 | G5: 1 | H5: 7.8 | J5: 1 | K5: 18.8
A6: 2 | B6: 0 | D6: 2 | E6: 1.4 | G6: 2 | H6: 1 | J6: 2 | K6: 19.8
A7: 3 | B7: 0 | D7: 3 | E7: 7.8 | G7: 3 | H7: 13.4 | J7: 3 | K7: 0
A8: 4 | B8: 0 | D8: 4 | E8: 29.6 | G8: 4 | H8: 64.2 | J8: 4 | K8: 0
A9: 5 | B9: 4.4 | D9: 5 | E9: 6 | G9: 5 | H9: 32.2 | J9: 5 | K9: 0
A10: 6 | B10: 5.6 | D10: 6 | E10: 0 | G10: 6 | H10: 2.8 | J10: 6 | K10: 5
A11: 7 | B11: 5 | D11: 7 | E11: 0 | G11: 7 | H11: 0 | J11: 7 | K11: 20.4
A12: 8 | B12: 2.6 | D12: 8 | E12: 0 | G12: 8 | H12: 0 | J12: 8 | K12: 24.8
A13: 9 | B13: 0.2 | D13: 9 | E13: 1 | G13: 9 | H13: 0.8 | J13: 9 | K13: 34
A14: 10 | B14: 0 | D14: 10 | E14: 0.6 | G14: 10 | H14: 0 | J14: 10 | K14: 44.6
A15: 11 | B15: 0 | D15: 11 | E15: 1.6 | G15: 11 | H15: 0 | J15: 11 | K15: 14.4
A16: 12 | B16: 0 | D16: 12 | E16: 0 | G16: 12 | H16: 0 | J16: 12 | K16: 50.2
... A369: 365 | B369: 0.2 | D369: 365 | E369: 0 | G369: 365 | H369: 0 | J369: 365 | K369: 0

Sheet Studio Rain System
A1: RWH Input-Output Data
A2: Team J-9
A3: RED IS INPUT ONLY, TYPE NEW VALUES INTO RED
A5: Parameter | B5: Value | C5: Units | M5: Month
A6: Tank Parameters | M6: [-]
A7: Catchment Area | B7: ='Organized Input Output'!J7 -> 1100 | C7: m^2 | M7: Jan
A8: V_tank | B8: ='Organized Input Output'!H9 -> 20 | C8: m^3 | M8: Feb
A9: V_initial | B9: 0 | C9: m^3 | M9: Mar
A10: Consumption Parameters | G10: Number of Days | M10: Apr
A11: Consumption | B11: ='Organized Input Output'!D14 -> 745 | C11: L/day | D11: =B11/1000 -> 0.745 | E11: m^3/day | G11: 365 | J11: Max volume collected in one day | M11: May
